Workbook
Name Slicer_Country: #N/A
Name Slicer_Department: #N/A

Sheet NZ Staff
C1: Employee Data
C5: Name | D5: Gender | E5: Department | F5: Age | G5: Date Joined | H5: Salary | I5: Rating
C6: Lindy Guillet | D6: Male | E6: Sales | F6: 22 | G6: 44446 | H6: 112780 | I6: Above average
C7: Ambros Murthwaite | D7: Male | E7: Procurement | F7: 46 | G7: 44758 | H7: 70610 | I7: Average
C8: Tatum Hush | D8: Female | E8: Sales | F8: 28 | G8: 44357 | H8: 53240 | I8: Average
C9: Benny Karolovsky | E9: Finance | F9: 37 | G9: 44146 | H9: 115440 | I9: Poor
C10: Hoyt D'Alesco | D10: Male | E10: Sales | F10: 32 | G10: 44465 | H10: 53540 | I10: Average
C11: Halimeda Kuscha | D11: Female | E11: Procurement | F11: 30 | G11: 44861 | H11: 112570 | I11: Average
C12: Erin Androsik | D12: Male | E12: Procurement | F12: 33 | G12: 44701 | H12: 48530 | I12: Above average
C13: Vic Radolf | D13: Female | E13: Website | F13: 24 | G13: 44148 | H13: 62780 | I13: Average
C14: William Reeveley | D14: Male | E14: Website | F14: 33 | G14: 44509 | H14: 53870 | I14: Average
C15: Ewart Laphorn | D15: Female | E15: HR | F15: 27 | G15: 44122 | H15: 119110 | I15: Average
C16: Bev Lashley | D16: Male | E16: Website | F16: 29 | G16: 44180 | H16: 112110 | I16: Poor
C17: Kath Bletsoe | D17: Male | E17: Sales | F17: 25 | G17: 44383 | H17: 65700 | I17: Average
C18: Murry Dryburgh | D18: Male | E18: Website | F18: 37 | G18: 44701 | H18: 69070 | I18: Average
C19: Kaine Padly | D19: Male | E19: Website | F19: 20 | G19: 44459 | H19: 107700 | I19: Average
C20: Kassi Jonson | D20: Female | E20: Website | F20: 32 | G20: 44354 | H20: 43840 | I20: Above average
C21: Simon Kembery | D21: Male | E21: Procurement | F21: 40 | G21: 44263 | H21: 99750 | I21: Average
... C29: Esmaria Denecamp | D29: Male | E29: Finance | F29: 27 | G29: 44567 | H29: 48980 | I29: Average
C30: Curtice Advani | E30: Finance | F30: 30 | G30: 44597 | H30: 64000 | I30: Average
C31: Barr Faughny | D31: Female | E31: Procurement | F31: 42 | G31: 44779 | H31: 75000 | I31: Exceptional
C32: Merrilee Plenty | D32: Female | E32: Website | F32: 40 | G32: 44337 | H32: 87620 | I32: Average
C33: Niall Selesnick | D33: Female | E33: Website | F33: 29 | G33: 44023 | H33: 34980 | I33: Average
C34: Beverie Moffet | D34: Female | E34: Finance | F34: 28 | G34: 44185 | H34: 75970 | I34: Average
C35: Jehu Rudeforth | D35: Female | E35: Finance | F35: 34 | G35: 44612 | H35: 60130 | I35: Average
C36: Camilla Castle | D36: Female | E36: Website | F36: 33 | G36: 44374 | H36: 75480 | I36: Very poor
C37: Roddy Speechley | D37: Male | E37: Procurement | F37: 33 | G37: 44164 | H37: 115920 | I37: Average
C38: Gray Seamon | D38: Female | E38: Sales | F38: 36 | G38: 44494 | H38: 78540 | I38: Average
C39: Madelene Upcott | D39: Male | E39: Procurement | F39: 25 | G39: 44726 | H39: 109190 | I39: Above average
C40: Violante Courtonne | D40: Female | E40: Sales | F40: 34 | G40: 44721 | H40: 49630 | I40: Poor
C41: Bernie Gorges | D41: Female | E41: Procurement | F41: 28 | G41: 44630 | H41: 99970 | I41: Average
C42: Torrance Collier | D42: Female | E42: Website | F42: 33 | G42: 44190 | H42: 96140 | I42: Average
... C67: Wilone O'Kielt | D67: Female | E67: Website | F67: 43 | G67: 45045 | H67: 114870 | I67: Average
C68: Madge McCloughen | E68: Website | F68: 32 | G68: 44774 | H68: 91310 | I68: Average
C69: Janene Hairsine | D69: Female | E69: Procurement | F69: 28 | G69: 44486 | H69: 104770 | I69: Average
C70: Alta Kaszper | D70: Male | E70: Sales | F70: 27 | G70: 44134 | H70: 54970 | I70: Average
C71: Dennison Crosswaite | E71: Website | F71: 26 | G71: 44271 | H71: 90700 | I71: Above average
C72: Oran Buxcy | D72: Female | E72: Sales | F72: 38 | G72: 44329 | H72: 56870 | I72: Above average
C73: Hinda Label | D73: Female | E73: Sales | F73: 25 | G73: 44205 | H73: 92700 | I73: Average
C74: Marney O'Breen | D74: Female | E74: Finance | F74: 21 | G74: 44317 | H74: 65920 | I74: Average
...

Sheet India Staff
B2: Name | C2: Gender | D2: Age | E2: Rating | F2: Date Joined | G2: Department | H2: Salary
B3: Deepali Charan | C3: Male | D3: 20 | E3: Average | F3: 44122 | G3: Website | H3: 112650
B4: Yagna Sujeev | C4: Female | D4: 32 | E4: Above average | F4: 44293 | G4: Website | H4: 43840
B5: Satyendra Venkatadri | C5: Male | D5: 31 | E5: Average | F5: 44663 | G5: Procurement | H5: 103550
B6: Madhavdas Buhpathi | C6: Female | D6: 32 | E6: Average | F6: 44339 | G6: HR | H6: 45510
B7: Sahila Chandrasekhar | D7: 37 | E7: Poor | F7: 44085 | G7: Finance | H7: 115440
B8: Mirium Seemantini Shivakumar | C8: Female | D8: 38 | E8: Above average | F8: 44268 | G8: Sales | H8: 56870
B9: Purnendu Vijayarangan | C9: Female | D9: 25 | E9: Average | F9: 44144 | G9: Sales | H9: 92700
B10: Rukma Vinita | D10: 32 | E10: Average | F10: 44713 | G10: Website | H10: 91310
B11: Yauvani Tarpa | C11: Male | D11: 33 | E11: Average | F11: 44324 | G11: Sales | H11: 74550
B12: Damayanti Thangavadivelu | C12: Male | D12: 25 | E12: Above average | F12: 44665 | G12: Procurement | H12: 109190
B13: Manjusri Ruchi | C13: Female | D13: 40 | E13: Average | F13: 44320 | G13: Website | H13: 104410
B14: Mithil Nadkarni | C14: Male | D14: 30 | E14: Average | F14: 44544 | G14: Finance | H14: 96800
B15: Ardhendu Abhichandra Jayakar | C15: Male | D15: 28 | E15: Above average | F15: 43980 | G15: Finance | H15: 48170
B16: Akbar Sorabhjee | C16: Male | D16: 21 | E16: Average | F16: 44042 | G16: Procurement | H16: 37920
B17: Bandhula Sathyanna | C17: Male | D17: 34 | E17: Average | F17: 44642 | G17: Procurement | H17: 112650
B18: Daruka Ghazali | C18: Female | D18: 34 | E18: Poor | F18: 44660 | G18: Sales | H18: 49630
B19: Heer Pennathur | C19: Male | D19: 36 | E19: Average | F19: 43958 | G19: Website | H19: 118840
B20: Shekhar Eswara | C20: Male | D20: 30 | E20: Average | F20: 44789 | G20: Website | H20: 69710
B21: Udyan Lanka | C21: Male | D21: 20 | E21: Average | F21: 44683 | G21: Procurement | H21: 79570
B22: Shreela Ramasubraman | C22: Female | D22: 22 | E22: Above average | F22: 44388 | G22: Procurement | H22: 76900
... B53: Indu Varada Sumedh | C53: Female | D53: 28 | E53: Average | F53: 44124 | G53: Finance | H53: 75970
B54: Karuna Pashupathy | D54: 27 | E54: Above average | F54: 44212 | G54: Website | H54: 90700
B55: Mardav Ramaswami | C55: Male | D55: 30 | E55: Average | F55: 44607 | G55: Procurement | H55: 60570
B56: Sarayu Ragunathan | C56: Male | D56: 33 | E56: Average | F56: 44103 | G56: Procurement | H56: 115920
B57: Kevalkumar Solanki | C57: Female | D57: 33 | E57: Average | F57: 44006 | G57: Finance | H57: 65360
B58: Upendra Swati | D58: 30 | E58: Average | F58: 44535 | G58: Finance | H58: 64000
B59: Deepit Ranjana | C59: Female | D59: 34 | E59: Average | F59: 44383 | G59: Finance | H59: 92450
B60: Amal Nimesh | C60: Male | D60: 31 | E60: Average | F60: 44450 | G60: Website | H60: 48950
B61: Kunja Prashanta Vibha | C61: Female | D61: 27 | E61: Average | F61: 44625 | G61: Website | H61: 83750
B62: Godavari Veena | C62: Female | D62: 40 | E62: Average | F62: 44276 | G62: Website | H62: 87620
B63: Devasree Fullara Saurin | C63: Female | D63: 20 | E63: Poor | F63: 44476 | G63: Sales | H63: 68900
B64: Geena Raghavanpillai | C64: Male | D64: 32 | E64: Average | F64: 44403 | G64: Sales | H64: 53540
B65: Rupak Mehra | C65: Male | D65: 28 | E65: Very poor | F65: 44758 | G65: Sales | H65: 43510
B66: Sawini Chandan | C66: Female | D66: 38 | E66: Exceptional | F66: 44316 | G66: Sales | H66: 109160
B67: Baruna Ogale | C67: Male | D67: 40 | E67: Average | F67: 44204 | G67: Procurement | H67: 99750
B68: Jagajeet Viraj | C68: Female | D68: 31 | E68: Average | F68: 44084 | G68: Website | H68: 41980
B69: Kulbhushan Moorthy | C69: Male | D69: 36 | E69: Average | F69: 44272 | G69: Finance | H69: 71380
B70: Ilesh Dasgupta | C70: Male | D70: 27 | E70: Very poor | F70: 44547 | G70: Procurement | H70: 113280
... B98: Madhavdas Buhpathi | C98: Female | D98: 32 | E98: Average | F98: 44339 | G98: HR | H98: 45510
...

Sheet All Staff
A1: Name | B1: Gender | C1: Department | D1: Age | E1: Date Joined | F1: Salary | G1: Rating | H1: Country | I1: Tenure | J1: Bonus | K1: Rating As Number
A2: Gretchen Callow | B2: Female | C2: Website | D2: 21 | E2: 44678 | F2: 33920 | G2: Average | H2: nz | I2: =(TODAY()-staff[[#This Row],[Date Joined]])/365 -> 4.2246575 | J2: =ROUNDUP(IF(staff[[#This Row],[Tenure]]>2,3%,2%)*staff[[#This Row],[Salary]],0) -> 1018 | K2: =_xlfn.XLOOKUP(staff[[#This Row],[Rating]],'Rating map table'!A$2:A$6,'Rating map table'!B$2:B$6) -> 3
A3: Shubhra Potla | B3: Female | C3: Website | D3: 21 | E3: 44619 | F3: 33920 | G3: Average | H3: India | I3: =(TODAY()-staff[[#This Row],[Date Joined]])/365 -> 4.3863014 | J3: =ROUNDUP(IF(staff[[#This Row],[Tenure]]>2,3%,2%)*staff[[#This Row],[Salary]],0) -> 1018 | K3: =_xlfn.XLOOKUP(staff[[#This Row],[Rating]],'Rating map table'!A$2:A$6,'Rating map table'!B$2:B$6) -> 3
A4: Niall Selesnick | B4: Female | C4: Website | D4: 29 | E4: 44023 | F4: 34980 | G4: Average | H4: nz | I4: =(TODAY()-staff[[#This Row],[Date Joined]])/365 -> 6.0191781 | J4: =ROUNDUP(IF(staff[[#This Row],[Tenure]]>2,3%,2%)*staff[[#This Row],[Salary]],0) -> 1050 | K4: =_xlfn.XLOOKUP(staff[[#This Row],[Rating]],'Rating map table'!A$2:A$6,'Rating map table'!B$2:B$6) -> 3
A5: Suchira Bhanupriya Tapti | B5: Female | C5: Website | D5: 29 | E5: 43962 | F5: 34980 | G5: Average | H5: India | I5: =(TODAY()-staff[[#This Row],[Date Joined]])/365 -> 6.1863014 | J5: =ROUNDUP(IF(staff[[#This Row],[Tenure]]>2,3%,2%)*staff[[#This Row],[Salary]],0) -> 1050 | K5: =_xlfn.XLOOKUP(staff[[#This Row],[Rating]],'Rating map table'!A$2:A$6,'Rating map table'!B$2:B$6) -> 3
A6: Bili Sizey | B6: Male | C6: Sales | D6: 43 | E6: 44620 | F6: 36040 | G6: Average | H6: nz | I6: =(TODAY()-staff[[#This Row],[Date Joined]])/365 -> 4.3835616 | J6: =ROUNDUP(IF(staff[[#This Row],[Tenure]]>2,3%,2%)*staff[[#This Row],[Salary]],0) -> 1082 | K6: =_xlfn.XLOOKUP(staff[[#This Row],[Rating]],'Rating map table'!A$2:A$6,'Rating map table'!B$2:B$6) -> 3
A7: Waheeda Vasuman | B7: Male | C7: Sales | D7: 43 | E7: 44558 | F7: 36040 | G7: Average | H7: India | I7: =(TODAY()-staff[[#This Row],[Date Joined]])/365 -> 4.5534247 | J7: =ROUNDUP(IF(staff[[#This Row],[Tenure]]>2,3%,2%)*staff[[#This Row],[Salary]],0) -> 1082 | K7: =_xlfn.XLOOKUP(staff[[#This Row],[Rating]],'Rating map table'!A$2:A$6,'Rating map table'!B$2:B$6) -> 3
A8: Orton Livick | B8: Male | C8: Procurement | D8: 21 | E8: 44104 | F8: 37920 | G8: Average | H8: nz | I8: =(TODAY()-staff[[#This Row],[Date Joined]])/365 -> 5.7972603 | J8: =ROUNDUP(IF(staff[[#This Row],[Tenure]]>2,3%,2%)*staff[[#This Row],[Salary]],0) -> 1138 | K8: =_xlfn.XLOOKUP(staff[[#This Row],[Rating]],'Rating map table'!A$2:A$6,'Rating map table'!B$2:B$6) -> 3
A9: Akbar Sorabhjee | B9: Male | C9: Procurement | D9: 21 | E9: 44042 | F9: 37920 | G9: Average | H9: India | I9: =(TODAY()-staff[[#This Row],[Date Joined]])/365 -> 5.9671233 | J9: =ROUNDUP(IF(staff[[#This Row],[Tenure]]>2,3%,2%)*staff[[#This Row],[Salary]],0) -> 1138 | K9: =_xlfn.XLOOKUP(staff[[#This Row],[Rating]],'Rating map table'!A$2:A$6,'Rating map table'!B$2:B$6) -> 3
A10: Archibald Filliskirk | B10: Male | C10: Procurement | D10: 35 | E10: 44727 | F10: 40400 | G10: Average | H10: nz | I10: =(TODAY()-staff[[#This Row],[Date Joined]])/365 -> 4.090411 | J10: =ROUNDUP(IF(staff[[#This Row],[Tenure]]>2,3%,2%)*staff[[#This Row],[Salary]],0) -> 1212 | K10: =_xlfn.XLOOKUP(staff[[#This Row],[Rating]],'Rating map table'!A$2:A$6,'Rating map table'!B$2:B$6) -> 3
A11: Shobhana Samuel | B11: Male | C11: Procurement | D11: 35 | E11: 44666 | F11: 40400 | G11: Average | H11: India | I11: =(TODAY()-staff[[#This Row],[Date Joined]])/365 -> 4.2575342 | J11: =ROUNDUP(IF(staff[[#This Row],[Tenure]]>2,3%,2%)*staff[[#This Row],[Salary]],0) -> 1212 | K11: =_xlfn.XLOOKUP(staff[[#This Row],[Rating]],'Rating map table'!A$2:A$6,'Rating map table'!B$2:B$6) -> 3 | N11: Count of Employees | O11: =COUNTA(staff[Name]) -> 183 | P11: Median
A12: Crissie Cordel | B12: Female | C12: Procurement | D12: 32 | E12: 44611 | F12: 41570 | G12: Average | H12: nz | I12: =(TODAY()-staff[[#This Row],[Date Joined]])/365 -> 4.4082192 | J12: =ROUNDUP(IF(staff[[#This Row],[Tenure]]>2,3%,2%)*staff[[#This Row],[Salary]],0) -> 1248 | K12: =_xlfn.XLOOKUP(staff[[#This Row],[Rating]],'Rating map table'!A$2:A$6,'Rating map table'!B$2:B$6) -> 3 | N12: Average Salary | O12: =AVERAGE(staff[[#All],[Salary]]) -> 77173.716 | P12: =MEDIAN(staff[[#All],[Salary]]) -> 75000
A13: Prerana Nishita | B13: Female | C13: Procurement | D13: 32 | E13: 44549 | F13: 41570 | G13: Average | H13: India | I13: =(TODAY()-staff[[#This Row],[Date Joined]])/365 -> 4.5780822 | J13: =ROUNDUP(IF(staff[[#This Row],[Tenure]]>2,3%,2%)*staff[[#This Row],[Salary]],0) -> 1248 | K13: =_xlfn.XLOOKUP(staff[[#This Row],[Rating]],'Rating map table'!A$2:A$6,'Rating map table'!B$2:B$6) -> 3 | N13: Average Age | O13: =AVERAGE(staff[[#All],[Age]]) -> 30.42623 | P13: =MEDIAN(staff[[#All],[Age]]) -> 30
A14: Dotty Strutley | B14: Female | C14: Website | D14: 31 | E14: 44145 | F14: 41980 | G14: Average | H14: nz | I14: =(TODAY()-staff[[#This Row],[Date Joined]])/365 -> 5.6849315 | J14: =ROUNDUP(IF(staff[[#This Row],[Tenure]]>2,3%,2%)*staff[[#This Row],[Salary]],0) -> 1260 | K14: =_xlfn.XLOOKUP(staff[[#This Row],[Rating]],'Rating map table'!A$2:A$6,'Rating map table'!B$2:B$6) -> 3 | N14: Average Tenure | O14: =AVERAGE(staff[[#All],[Tenure]]) -> 4.8958006
A15: Jagajeet Viraj | B15: Female | C15: Website | D15: 31 | E15: 44084 | F15: 41980 | G15: Average | H15: India | I15: =(TODAY()-staff[[#This Row],[Date Joined]])/365 -> 5.8520548 | J15: =ROUNDUP(IF(staff[[#This Row],[Tenure]]>2,3%,2%)*staff[[#This Row],[Salary]],0) -> 1260 | K15: =_xlfn.XLOOKUP(staff[[#This Row],[Rating]],'Rating map table'!A$2:A$6,'Rating map table'!B$2:B$6) -> 3 | N15: Female Count | O15: =COUNTIF(staff[Gender],"Female") -> 86
A16: Drusy MacCombe | B16: Male | C16: Sales | D16: 28 | E16: 44820 | F16: 43510 | G16: Very poor | H16: nz | I16: =(TODAY()-staff[[#This Row],[Date Joined]])/365 -> 3.8356164 | J16: =ROUNDUP(IF(staff[[#This Row],[Tenure]]>2,3%,2%)*staff[[#This Row],[Salary]],0) -> 1306 | K16: =_xlfn.XLOOKUP(staff[[#This Row],[Rating]],'Rating map table'!A$2:A$6,'Rating map table'!B$2:B$6) -> 1 | N16: Female Ratio % | O16: =O15/O11 -> 0.46994536
A17: Rupak Mehra | B17: Male | C17: Sales | D17: 28 | E17: 44758 | F17: 43510 | G17: Very poor | H17: India | I17: =(TODAY()-staff[[#This Row],[Date Joined]])/365 -> 4.0054795 | J17: =ROUNDUP(IF(staff[[#This Row],[Tenure]]>2,3%,2%)*staff[[#This Row],[Salary]],0) -> 1306 | K17: =_xlfn.XLOOKUP(staff[[#This Row],[Rating]],'Rating map table'!A$2:A$6,'Rating map table'!B$2:B$6) -> 1 | N17: Ratio of 90,000$> | O17: =(COUNTIF(staff[Salary],">90000"))/O11 -> 0.3442623
A18: Kassi Jonson | B18: Female | C18: Website | D18: 32 | E18: 44354 | F18: 43840 | G18: Above average | H18: nz | I18: =(TODAY()-staff[[#This Row],[Date Joined]])/365 -> 5.1123288 | J18: =ROUNDUP(IF(staff[[#This Row],[Tenure]]>2,3%,2%)*staff[[#This Row],[Salary]],0) -> 1316 | K18: =_xlfn.XLOOKUP(staff[[#This Row],[Rating]],'Rating map table'!A$2:A$6,'Rating map table'!B$2:B$6) -> 4
A19: Yagna Sujeev | B19: Female | C19: Website | D19: 32 | E19: 44293 | F19: 43840 | G19: Above average | H19: India | I19: =(TODAY()-staff[[#This Row],[Date Joined]])/365 -> 5.2794521 | J19: =ROUNDUP(IF(staff[[#This Row],[Tenure]]>2,3%,2%)*staff[[#This Row],[Salary]],0) -> 1316 | K19: =_xlfn.XLOOKUP(staff[[#This Row],[Rating]],'Rating map table'!A$2:A$6,'Rating map table'!B$2:B$6) -> 4
A20: Florinda Crace | B20: Female | C20: HR | D20: 32 | E20: 44400 | F20: 45510 | G20: Average | H20: nz | I20: =(TODAY()-staff[[#This Row],[Date Joined]])/365 -> 4.9863014 | J20: =ROUNDUP(IF(staff[[#This Row],[Tenure]]>2,3%,2%)*staff[[#This Row],[Salary]],0) -> 1366 | K20: =_xlfn.XLOOKUP(staff[[#This Row],[Rating]],'Rating map table'!A$2:A$6,'Rating map table'!B$2:B$6) -> 3
A21: Madhavdas Buhpathi | B21: Female | C21: HR | D21: 32 | E21: 44339 | F21: 45510 | G21: Average | H21: India | I21: =(TODAY()-staff[[#This Row],[Date Joined]])/365 -> 5.1534247 | J21: =ROUNDUP(IF(staff[[#This Row],[Tenure]]>2,3%,2%)*staff[[#This Row],[Salary]],0) -> 1366 | K21: =_xlfn.XLOOKUP(staff[[#This Row],[Rating]],'Rating map table'!A$2:A$6,'Rating map table'!B$2:B$6) -> 3
A22: Dell Molloy | B22: Male | C22: Procurement | D22: 26 | E22: 44225 | F22: 47360 | G22: Average | H22: nz | I22: =(TODAY()-staff[[#This Row],[Date Joined]])/365 -> 5.4657534 | J22: =ROUNDUP(IF(staff[[#This Row],[Tenure]]>2,3%,2%)*staff[[#This Row],[Salary]],0) -> 1421 | K22: =_xlfn.XLOOKUP(staff[[#This Row],[Rating]],'Rating map table'!A$2:A$6,'Rating map table'!B$2:B$6) -> 3
A23: Shiuli Sapna | B23: Male | C23: Procurement | D23: 26 | E23: 44164 | F23: 47360 | G23: Average | H23: India | I23: =(TODAY()-staff[[#This Row],[Date Joined]])/365 -> 5.6328767 | J23: =ROUNDUP(IF(staff[[#This Row],[Tenure]]>2,3%,2%)*staff[[#This Row],[Salary]],0) -> 1421 | K23: =_xlfn.XLOOKUP(staff[[#This Row],[Rating]],'Rating map table'!A$2:A$6,'Rating map table'!B$2:B$6) -> 3
A24: Jan Morforth | B24: Male | C24: Finance | D24: 28 | E24: 44041 | F24: 48170 | G24: Above average | H24: nz | I24: =(TODAY()-staff[[#This Row],[Date Joined]])/365 -> 5.969863 | J24: =ROUNDUP(IF(staff[[#This Row],[Tenure]]>2,3%,2%)*staff[[#This Row],[Salary]],0) -> 1446 | K24: =_xlfn.XLOOKUP(staff[[#This Row],[Rating]],'Rating map table'!A$2:A$6,'Rating map table'!B$2:B$6) -> 4
A25: Ardhendu Abhichandra Jayakar | B25: Male | C25: Finance | D25: 28 | E25: 43980 | F25: 48170 | G25: Above average | H25: India | I25: =(TODAY()-staff[[#This Row],[Date Joined]])/365 -> 6.1369863 | J25: =ROUNDUP(IF(staff[[#This Row],[Tenure]]>2,3%,2%)*staff[[#This Row],[Salary]],0) -> 1446 | K25: =_xlfn.XLOOKUP(staff[[#This Row],[Rating]],'Rating map table'!A$2:A$6,'Rating map table'!B$2:B$6) -> 4
A26: Erin Androsik | B26: Male | C26: Procurement | D26: 33 | E26: 44701 | F26: 48530 | G26: Above average | H26: nz | I26: =(TODAY()-staff[[#This Row],[Date Joined]])/365 -> 4.1616438 | J26: =ROUNDUP(IF(staff[[#This Row],[Tenure]]>2,3%,2%)*staff[[#This Row],[Salary]],0) -> 1456 | K26: =_xlfn.XLOOKUP(staff[[#This Row],[Rating]],'Rating map table'!A$2:A$6,'Rating map table'!B$2:B$6) -> 4
A27: Piyali Mahanthapa | B27: Male | C27: Procurement | D27: 33 | E27: 44640 | F27: 48530 | G27: Above average | H27: India | I27: =(TODAY()-staff[[#This Row],[Date Joined]])/365 -> 4.3287671 | J27: =ROUNDUP(IF(staff[[#This Row],[Tenure]]>2,3%,2%)*staff[[#This Row],[Salary]],0) -> 1456 | K27: =_xlfn.XLOOKUP(staff[[#This Row],[Rating]],'Rating map table'!A$2:A$6,'Rating map table'!B$2:B$6) -> 4
A28: Gunar Cockshoot | B28: Male | C28: Website | D28: 31 | E28: 44511 | F28: 48950 | G28: Average | H28: nz | I28: =(TODAY()-staff[[#This Row],[Date Joined]])/365 -> 4.6821918 | J28: =ROUNDUP(IF(staff[[#This Row],[Tenure]]>2,3%,2%)*staff[[#This Row],[Salary]],0) -> 1469 | K28: =_xlfn.XLOOKUP(staff[[#This Row],[Rating]],'Rating map table'!A$2:A$6,'Rating map table'!B$2:B$6) -> 3
A29: Amal Nimesh | B29: Male | C29: Website | D29: 31 | E29: 44450 | F29: 48950 | G29: Average | H29: India | I29: =(TODAY()-staff[[#This Row],[Date Joined]])/365 -> 4.8493151 | J29: =ROUNDUP(IF(staff[[#This Row],[Tenure]]>2,3%,2%)*staff[[#This Row],[Salary]],0) -> 1469 | K29: =_xlfn.XLOOKUP(staff[[#This Row],[Rating]],'Rating map table'!A$2:A$6,'Rating map table'!B$2:B$6) -> 3
... A184: Anjushri Chandiramani | B184: Female | C184: HR | D184: 27 | E184: 44061 | F184: 119110 | G184: Average | H184: India | I184: =(TODAY()-staff[[#This Row],[Date Joined]])/365 -> 5.9150685 | J184: =ROUNDUP(IF(staff[[#This Row],[Tenure]]>2,3%,2%)*staff[[#This Row],[Salary]],0) -> 3574 | K184: =_xlfn.XLOOKUP(staff[[#This Row],[Rating]],'Rating map table'!A$2:A$6,'Rating map table'!B$2:B$6) -> 3

Sheet Name Searcher
C4: type the name here
C5: Oby Sorrel
B6: Gender | C6: {=TRANSPOSE(_xlfn.XLOOKUP(C5,staff[Name],staff[[Gender]:[Tenure]]))} -> Female
B7: Department | C7: Finance
B8: Age | C8: 34
B9: Date Joined | C9: 44653
B10: Salary | C10: 58940
B11: Rating | C11: Average
B12: Country | C12: nz
B13: Tenure | C13: 4.2931507

Sheet India vs NZ Card
C1: NEWZELAND | K1: INDIA
C2: =COUNTIF(staff[],"nz") -> 91 | E2: =COUNTIFS(staff[Country],"nz",staff[Gender],"female")/C2 -> 0.47252747 | G2: =AVERAGEIF(staff[Country],"nz",staff[Salary]) -> 76978.791 | K2: =COUNTIF(staff[],"india") -> 92 | M2: =COUNTIFS(staff[Country],"india",staff[Gender],"female")/K2 -> 0.4673913 | O2: =AVERAGEIF(staff[Country],"india",staff[Salary]) -> 77366.522
C4: Headcount by Department

Sheet India vs NZ Pivot Table
B2: Country | C2: India | I2: Country | J2: nz
B4: Row Labels | C4: Count of Name | I4: Row Labels | J4: Count of Name
B5: Procurement | C5: 28 | I5: Website | J5: 27
B6: Website | C6: 27 | I6: Procurement | J6: 27
B7: Finance | C7: 19 | I7: Finance | J7: 19
B8: Sales | C8: 14 | I8: Sales | J8: 14
B9: HR | C9: 4 | I9: HR | J9: 4
C11: Column Labels
C12: India | F12: India Total | G12: nz | J12: nz Total
B13: Values | C13: Female | D13: Male | E13: other | G13: Female | H13: Male | I13: other
B14: amount of gender | C14: 43 | D14: 45 | E14: 4 | F14: 92 | G14: 43 | H14: 44 | I14: 4 | J14: 91
B15: percent of gender | C15: 0.4673913 | D15: 0.48913043 | E15: 0.043478261 | F15: 0.50273224 | G15: 0.47252747 | H15: 0.48351648 | I15: 0.043956044 | J15: 0.49726776
B16: Average of Salary | C16: 78284.186 | D16: 75334.444 | E16: 90362.5 | F16: 77366.522 | G16: 78284.186 | H16: 74564.318 | I16: 89505 | J16: 76978.791

Sheet Employement Growth
V5: Month-Year | W5: Headcount | X5: Running Total
C6: Row Labels | D6: Count of Employees Joined | E6: Running Total | U6: {=_xlfn.SEQUENCE(36)} -> 1 | V6: {=EDATE(DATE(2020,4,1),_xlfn.ANCHORARRAY(U6)+0)} -> 43952 | W6: =COUNTIFS(staff[Date Joined],">="&V6,staff[Date Joined],"<="&EOMONTH(V6,0)) -> 3 | X6: =SUM($W$6:W6) -> 3
C7: 2020 | U7: 2 | V7: 43983 | W7: =COUNTIFS(staff[Date Joined],">="&V7,staff[Date Joined],"<="&EOMONTH(V7,0)) -> 1 | X7: =SUM($W$6:W7) -> 4
C8: May | D8: 3 | E8: 3 | U8: 3 | V8: 44013 | W8: =COUNTIFS(staff[Date Joined],">="&V8,staff[Date Joined],"<="&EOMONTH(V8,0)) -> 5 | X8: =SUM($W$6:W8) -> 9
C9: Jun | D9: 1 | E9: 4 | U9: 4 | V9: 44044 | W9: =COUNTIFS(staff[Date Joined],">="&V9,staff[Date Joined],"<="&EOMONTH(V9,0)) -> 3 | X9: =SUM($W$6:W9) -> 12
C10: Jul | D10: 5 | E10: 9 | U10: 5 | V10: 44075 | W10: =COUNTIFS(staff[Date Joined],">="&V10,staff[Date Joined],"<="&EOMONTH(V10,0)) -> 6 | X10: =SUM($W$6:W10) -> 18
C11: Aug | D11: 3 | E11: 12 | U11: 6 | V11: 44105 | W11: =COUNTIFS(staff[Date Joined],">="&V11,staff[Date Joined],"<="&EOMONTH(V11,0)) -> 6 | X11: =SUM($W$6:W11) -> 24
C12: Sep | D12: 6 | E12: 18 | U12: 7 | V12: 44136 | W12: =COUNTIFS(staff[Date Joined],">="&V12,staff[Date Joined],"<="&EOMONTH(V12,0)) -> 6 | X12: =SUM($W$6:W12) -> 30
C13: Oct | D13: 6 | E13: 24 | U13: 8 | V13: 44166 | W13: =COUNTIFS(staff[Date Joined],">="&V13,staff[Date Joined],"<="&EOMONTH(V13,0)) -> 7 | X13: =SUM($W$6:W13) -> 37
C14: Nov | D14: 6 | E14: 30 | U14: 9 | V14: 44197 | W14: =COUNTIFS(staff[Date Joined],">="&V14,staff[Date Joined],"<="&EOMONTH(V14,0)) -> 6 | X14: =SUM($W$6:W14) -> 43
C15: Dec | D15: 7 | E15: 37 | U15: 10 | V15: 44228 | W15: =COUNTIFS(staff[Date Joined],">="&V15,staff[Date Joined],"<="&EOMONTH(V15,0)) -> 4 | X15: =SUM($W$6:W15) -> 47
C16: 2021 | U16: 11 | V16: 44256 | W16: =COUNTIFS(staff[Date Joined],">="&V16,staff[Date Joined],"<="&EOMONTH(V16,0)) -> 9 | X16: =SUM($W$6:W16) -> 56
C17: Jan | D17: 6 | E17: 6 | U17: 12 | V17: 44287 | W17: =COUNTIFS(staff[Date Joined],">="&V17,staff[Date Joined],"<="&EOMONTH(V17,0)) -> 5 | X17: =SUM($W$6:W17) -> 61
C18: Feb | D18: 4 | E18: 10 | U18: 13 | V18: 44317 | W18: =COUNTIFS(staff[Date Joined],">="&V18,staff[Date Joined],"<="&EOMONTH(V18,0)) -> 10 | X18: =SUM($W$6:W18) -> 71
C19: Mar | D19: 9 | E19: 19 | U19: 14 | V19: 44348 | W19: =COUNTIFS(staff[Date Joined],">="&V19,staff[Date Joined],"<="&EOMONTH(V19,0)) -> 6 | X19: =SUM($W$6:W19) -> 77
C20: Apr | D20: 5 | E20: 24 | U20: 15 | V20: 44378 | W20: =COUNTIFS(staff[Date Joined],">="&V20,staff[Date Joined],"<="&EOMONTH(V20,0)) -> 13 | X20: =SUM($W$6:W20) -> 90
C21: May | D21: 10 | E21: 34 | U21: 16 | V21: 44409 | W21: =COUNTIFS(staff[Date Joined],">="&V21,staff[Date Joined],"<="&EOMONTH(V21,0)) -> 4 | X21: =SUM($W$6:W21) -> 94
C22: Jun | D22: 6 | E22: 40 | U22: 17 | V22: 44440 | W22: =COUNTIFS(staff[Date Joined],">="&V22,staff[Date Joined],"<="&EOMONTH(V22,0)) -> 11 | X22: =SUM($W$6:W22) -> 105
C23: Jul | D23: 13 | E23: 53 | U23: 18 | V23: 44470 | W23: =COUNTIFS(staff[Date Joined],">="&V23,staff[Date Joined],"<="&EOMONTH(V23,0)) -> 3 | X23: =SUM($W$6:W23) -> 108
C24: Aug | D24: 4 | E24: 57 | U24: 19 | V24: 44501 | W24: =COUNTIFS(staff[Date Joined],">="&V24,staff[Date Joined],"<="&EOMONTH(V24,0)) -> 4 | X24: =SUM($W$6:W24) -> 112
C25: Sep | D25: 11 | E25: 68 | U25: 20 | V25: 44531 | W25: =COUNTIFS(staff[Date Joined],">="&V25,staff[Date Joined],"<="&EOMONTH(V25,0)) -> 7 | X25: =SUM($W$6:W25) -> 119
C26: Oct | D26: 3 | E26: 71 | U26: 21 | V26: 44562 | W26: =COUNTIFS(staff[Date Joined],">="&V26,staff[Date Joined],"<="&EOMONTH(V26,0)) -> 3 | X26: =SUM($W$6:W26) -> 122
C27: Nov | D27: 4 | E27: 75 | U27: 22 | V27: 44593 | W27: =COUNTIFS(staff[Date Joined],">="&V27,staff[Date Joined],"<="&EOMONTH(V27,0)) -> 10 | X27: =SUM($W$6:W27) -> 132
C28: Dec | D28: 7 | E28: 82 | U28: 23 | V28: 44621 | W28: =COUNTIFS(staff[Date Joined],">="&V28,staff[Date Joined],"<="&EOMONTH(V28,0)) -> 9 | X28: =SUM($W$6:W28) -> 141
C29: 2022 | U29: 24 | V29: 44652 | W29: =COUNTIFS(staff[Date Joined],">="&V29,staff[Date Joined],"<="&EOMONTH(V29,0)) -> 9 | X29: =SUM($W$6:W29) -> 150
C30: Jan | D30: 3 | E30: 3 | U30: 25 | V30: 44682 | W30: =COUNTIFS(staff[Date Joined],">="&V30,staff[Date Joined],"<="&EOMONTH(V30,0)) -> 9 | X30: =SUM($W$6:W30) -> 159
C31: Feb | D31: 10 | E31: 13 | U31: 26 | V31: 44713 | W31: =COUNTIFS(staff[Date Joined],">="&V31,staff[Date Joined],"<="&EOMONTH(V31,0)) -> 7 | X31: =SUM($W$6:W31) -> 166
C32: Mar | D32: 9 | E32: 22 | U32: 27 | V32: 44743 | W32: =COUNTIFS(staff[Date Joined],">="&V32,staff[Date Joined],"<="&EOMONTH(V32,0)) -> 5 | X32: =SUM($W$6:W32) -> 171
C33: Apr | D33: 9 | E33: 31 | U33: 28 | V33: 44774 | W33: =COUNTIFS(staff[Date Joined],">="&V33,staff[Date Joined],"<="&EOMONTH(V33,0)) -> 5 | X33: =SUM($W$6:W33) -> 176
C34: May | D34: 9 | E34: 40 | U34: 29 | V34: 44805 | W34: =COUNTIFS(staff[Date Joined],">="&V34,staff[Date Joined],"<="&EOMONTH(V34,0)) -> 2 | X34: =SUM($W$6:W34) -> 178
C35: Jun | D35: 7 | E35: 47 | U35: 30 | V35: 44835 | W35: =COUNTIFS(staff[Date Joined],">="&V35,staff[Date Joined],"<="&EOMONTH(V35,0)) -> 3 | X35: =SUM($W$6:W35) -> 181
C36: Jul | D36: 5 | E36: 52 | U36: 31 | V36: 44866 | W36: =COUNTIFS(staff[Date Joined],">="&V36,staff[Date Joined],"<="&EOMONTH(V36,0)) -> 0 | X36: =SUM($W$6:W36) -> 181
C37: Aug | D37: 5 | E37: 57 | U37: 32 | V37: 44896 | W37: =COUNTIFS(staff[Date Joined],">="&V37,staff[Date Joined],"<="&EOMONTH(V37,0)) -> 0 | X37: =SUM($W$6:W37) -> 181
C38: Sep | D38: 2 | E38: 59 | U38: 33 | V38: 44927 | W38: =COUNTIFS(staff[Date Joined],">="&V38,staff[Date Joined],"<="&EOMONTH(V38,0)) -> 0 | X38: =SUM($W$6:W38) -> 181
C39: Oct | D39: 3 | E39: 62 | U39: 34 | V39: 44958 | W39: =COUNTIFS(staff[Date Joined],">="&V39,staff[Date Joined],"<="&EOMONTH(V39,0)) -> 1 | X39: =SUM($W$6:W39) -> 182
C40: 2023 | U40: 35 | V40: 44986 | W40: =COUNTIFS(staff[Date Joined],">="&V40,staff[Date Joined],"<="&EOMONTH(V40,0)) -> 0 | X40: =SUM($W$6:W40) -> 182
C41: Feb | D41: 1 | E41: 1 | U41: 36 | V41: 45017 | W41: =COUNTIFS(staff[Date Joined],">="&V41,staff[Date Joined],"<="&EOMONTH(V41,0)) -> 1 | X41: =SUM($W$6:W41) -> 183
C42: Apr | D42: 1 | E42: 2
C43: Grand Total | D43: 183

Sheet Salary vs Rating
B8: Row Labels | C8: Count of Name | D8: Average of Salary
B9: Exceptional | C9: 4 | D9: 92080
B10: Above average | C10: 20 | D10: 75933
B11: Average | C11: 137 | D11: 76798.759
B12: Poor | C12: 16 | D12: 78115
B13: Very poor | C13: 6 | D13: 77423.333
B14: Grand Total | C14: 183 | D14: 77173.716

Sheet Salary Spread

Sheet Information Finder
A1: Information Finder
A2: Based on department
C6: Name | H6: Salary | I6: Rating
C7: {=_xlfn._xlws.SORT(_xlfn._xlws.FILTER(staff[],staff[Department]=P10),6,-1)} -> Benny Karolovsky | D7: other | E7: Finance | F7: 37 | G7: 44146 | H7: 115440 | I7: Poor | J7: nz | K7: 5.6821918 | L7: 3464 | M7: 2
C8: Sahila Chandrasekhar | D8: other | E8: Finance | F8: 37 | G8: 44085 | H8: 115440 | I8: Poor | J8: India | K8: 5.8493151 | L8: 3464 | M8: 2
C9: Constantino Espley | D9: Male | E9: Finance | F9: 30 | G9: 44606 | H9: 96800 | I9: Average | J9: nz | K9: 4.4219178 | L9: 2904 | M9: 3 | P9: Type Here The Department
C10: Mithil Nadkarni | D10: Male | E10: Finance | F10: 30 | G10: 44544 | H10: 96800 | I10: Average | J10: India | K10: 4.5917808 | L10: 2904 | M10: 3 | O10: Department Name | P10: Finance
C11: Leilah Yesinin | D11: Female | E11: Finance | F11: 34 | G11: 44445 | H11: 92450 | I11: Average | J11: nz | K11: 4.8630137 | L11: 2774 | M11: 3 | O11: Number of Employees | P11: =COUNTIF(staff[Department],P10) -> 38
C12: Deepit Ranjana | D12: Female | E12: Finance | F12: 34 | G12: 44383 | H12: 92450 | I12: Average | J12: India | K12: 5.0328767 | L12: 2774 | M12: 3
C13: Enoch Dowrey | D13: Male | E13: Finance | F13: 27 | G13: 44236 | H13: 91650 | I13: Above average | J13: nz | K13: 5.4356164 | L13: 2750 | M13: 4
C14: Kamalakshi Mukundan | D14: Male | E14: Finance | F14: 27 | G14: 44174 | H14: 91650 | I14: Above average | J14: India | K14: 5.6054795 | L14: 2750 | M14: 4
C15: Sibyl Dunkirk | D15: Female | E15: Finance | F15: 33 | G15: 44809 | H15: 86570 | I15: Average | J15: nz | K15: 3.8657534 | L15: 2598 | M15: 3
C16: Madhumati Gazala Soumitra | D16: Female | E16: Finance | F16: 33 | G16: 44747 | H16: 86570 | I16: Average | J16: India | K16: 4.0356164 | L16: 2598 | M16: 3
C17: Karlen McCaffrey | D17: Female | E17: Finance | F17: 34 | G17: 44459 | H17: 85000 | I17: Average | J17: nz | K17: 4.8246575 | L17: 2550 | M17: 3
C18: Tarala Vishaal | D18: Female | E18: Finance | F18: 34 | G18: 44397 | H18: 85000 | I18: Average | J18: India | K18: 4.9945205 | L18: 2550 | M18: 3
C19: Beverie Moffet | D19: Female | E19: Finance | F19: 28 | G19: 44185 | H19: 75970 | I19: Average | J19: nz | K19: 5.5753425 | L19: 2280 | M19: 3
C20: Indu Varada Sumedh | D20: Female | E20: Finance | F20: 28 | G20: 44124 | H20: 75970 | I20: Average | J20: India | K20: 5.7424658 | L20: 2280 | M20: 3
C21: Bennie Pepis | D21: Male | E21: Finance | F21: 36 | G21: 44333 | H21: 71380 | I21: Average | J21: nz | K21: 5.169863 | L21: 2142 | M21: 3
C22: Kulbhushan Moorthy | D22: Male | E22: Finance | F22: 36 | G22: 44272 | H22: 71380 | I22: Average | J22: India | K22: 5.3369863 | L22: 2142 | M22: 3
C23: Shayne Stegel | D23: Male | E23: Finance | F23: 42 | G23: 44731 | H23: 70270 | I23: Poor | J23: nz | K23: 4.0794521 | L23: 2109 | M23: 2
... C44: Ardhendu Abhichandra Jayakar | D44: Male | E44: Finance | F44: 28 | G44: 43980 | H44: 48170 | I44: Above average | J44: India | K44: 6.1369863 | L44: 1446 | M44: 4

Sheet Gender pivot table
D8: Column Labels
C9: Values | D9: Female | E9: Male | F9: Grand Total
C10: Count of Name | D10: 86 | E10: 89 | F10: 175
C11: Average of Age | D11: 31.406977 | E11: 29.393258 | F11: 30.382857
C12: Sum of Salary | D12: 6732440 | E12: 6670880 | F12: 13403320
C13: Average of Salary2 | D13: 78284.186 | E13: 74953.708 | F13: 76590.4
C14: Average of Tenure | D14: 4.8983753 | E14: 4.891396 | F14: 4.8948258

Sheet Male vs Female
C4: {=_xlfn._xlws.FILTER(staff[],staff[Gender]= Q11)} -> Gretchen Callow | D4: Female | E4: Website | F4: 21 | G4: 44678 | H4: 33920 | I4: Average | J4: nz | K4: 4.2246575 | L4: 1018 | M4: 3
C5: Shubhra Potla | D5: Female | E5: Website | F5: 21 | G5: 44619 | H5: 33920 | I5: Average | J5: India | K5: 4.3863014 | L5: 1018 | M5: 3
C6: Niall Selesnick | D6: Female | E6: Website | F6: 29 | G6: 44023 | H6: 34980 | I6: Average | J6: nz | K6: 6.0191781 | L6: 1050 | M6: 3
C7: Suchira Bhanupriya Tapti | D7: Female | E7: Website | F7: 29 | G7: 43962 | H7: 34980 | I7: Average | J7: India | K7: 6.1863014 | L7: 1050 | M7: 3
C8: Crissie Cordel | D8: Female | E8: Procurement | F8: 32 | G8: 44611 | H8: 41570 | I8: Average | J8: nz | K8: 4.4082192 | L8: 1248 | M8: 3
C9: Prerana Nishita | D9: Female | E9: Procurement | F9: 32 | G9: 44549 | H9: 41570 | I9: Average | J9: India | K9: 4.5780822 | L9: 1248 | M9: 3
C10: Dotty Strutley | D10: Female | E10: Website | F10: 31 | G10: 44145 | H10: 41980 | I10: Average | J10: nz | K10: 5.6849315 | L10: 1260 | M10: 3 | Q10: Type Here The Gender
C11: Jagajeet Viraj | D11: Female | E11: Website | F11: 31 | G11: 44084 | H11: 41980 | I11: Average | J11: India | K11: 5.8520548 | L11: 1260 | M11: 3 | P11: GENDER: | Q11: female
C12: Kassi Jonson | D12: Female | E12: Website | F12: 32 | G12: 44354 | H12: 43840 | I12: Above average | J12: nz | K12: 5.1123288 | L12: 1316 | M12: 4 | P12: COUNT | Q12: =COUNTIF(staff[],Q11) -> 86
C13: Yagna Sujeev | D13: Female | E13: Website | F13: 32 | G13: 44293 | H13: 43840 | I13: Above average | J13: India | K13: 5.2794521 | L13: 1316 | M13: 4 | P13: max salary | Q13: =_xlfn.MAXIFS(staff[Salary],staff[Gender],Q11) -> 119110
C14: Florinda Crace | D14: Female | E14: HR | F14: 32 | G14: 44400 | H14: 45510 | I14: Average | J14: nz | K14: 4.9863014 | L14: 1366 | M14: 3 | P14: Average Salary | Q14: =AVERAGEIFS(staff[Salary],staff[Gender],Q11) -> 78284.186
C15: Madhavdas Buhpathi | D15: Female | E15: HR | F15: 32 | G15: 44339 | H15: 45510 | I15: Average | J15: India | K15: 5.1534247 | L15: 1366 | M15: 3 | P15: Average Age | Q15: =AVERAGEIFS(staff[Age],staff[Gender],Q11) -> 31.406977
C16: Violante Courtonne | D16: Female | E16: Sales | F16: 34 | G16: 44721 | H16: 49630 | I16: Poor | J16: nz | K16: 4.1068493 | L16: 1489 | M16: 2
C17: Daruka Ghazali | D17: Female | E17: Sales | F17: 34 | G17: 44660 | H17: 49630 | I17: Poor | J17: India | K17: 4.2739726 | L17: 1489 | M17: 2
C18: Tatum Hush | D18: Female | E18: Sales | F18: 28 | G18: 44357 | H18: 53240 | I18: Average | J18: nz | K18: 5.1041096 | L18: 1598 | M18: 3
C19: Anumati Shyamari Meherhomji | D19: Female | E19: Sales | F19: 28 | G19: 44296 | H19: 53240 | I19: Average | J19: India | K19: 5.2712329 | L19: 1598 | M19: 3
C20: Oran Buxcy | D20: Female | E20: Sales | F20: 38 | G20: 44329 | H20: 56870 | I20: Above average | J20: nz | K20: 5.1808219 | L20: 1707 | M20: 4
C21: Mirium Seemantini Shivakumar | D21: Female | E21: Sales | F21: 38 | G21: 44268 | H21: 56870 | I21: Above average | J21: India | K21: 5.3479452 | L21: 1707 | M21: 4
C22: Brien Boise | D22: Female | E22: Website | F22: 31 | G22: 44663 | H22: 58100 | I22: Average | J22: nz | K22: 4.2657534 | L22: 1743 | M22: 3
C23: Pratigya Rema | D23: Female | E23: Website | F23: 31 | G23: 44604 | H23: 58100 | I23: Average | J23: India | K23: 4.4273973 | L23: 1743 | M23: 3
C24: Oby Sorrel | D24: Female | E24: Finance | F24: 34 | G24: 44653 | H24: 58940 | I24: Average | J24: nz | K24: 4.2931507 | L24: 1769 | M24: 3
C25: Krittika Gaekwad | D25: Female | E25: Finance | F25: 34 | G25: 44594 | H25: 58940 | I25: Average | J25: India | K25: 4.4547945 | L25: 1769 | M25: 3
C26: Jehu Rudeforth | D26: Female | E26: Finance | F26: 34 | G26: 44612 | H26: 60130 | I26: Average | J26: nz | K26: 4.4054795 | L26: 1804 | M26: 3
C27: Lalit Kothari | D27: Female | E27: Finance | F27: 34 | G27: 44550 | H27: 60130 | I27: Average | J27: India | K27: 4.5753425 | L27: 1804 | M27: 3
... C89: Anjushri Chandiramani | D89: Female | E89: HR | F89: 27 | G89: 44061 | H89: 119110 | I89: Average | J89: India | K89: 5.9150685 | L89: 3574 | M89: 3

Sheet Rating map table
A1: Rating Map Table:
A2: Exceptional | B2: 5
A3: Above average | B3: 4
A4: Average | B4: 3
A5: Poor | B5: 2
A6: Very poor | B6: 1
